<mujoco model="Quadrotor">
  <compiler inertiafromgeom="true" coordinate="local"/>
  <option timestep="0.01" gravity="0 0 -9.81" wind="0 0 0" density="1.225" viscosity="1.48e-5" />

  <asset>
    <texture name="blue_grid" type="2d" builtin="checker" rgb1=".02 .14 .44" rgb2=".27 .55 1" width="300" height="300" mark="edge" markrgb="1 1 1"/>
    <material name="blue_grid" texture="blue_grid" texrepeat="1 1" texuniform="true" reflectance=".2"/>

    <texture name="grey_grid" type="2d" builtin="checker" rgb1=".26 .26 .26" rgb2=".6 .6 .6" width="300" height="300" mark="edge" markrgb="1 1 1"/>
    <material name="grey_grid" texture="blue_grid" texrepeat="1 1" texuniform="true" reflectance=".2"/>
    <texture name="skybox" type="skybox" builtin="gradient" rgb1=".66 .79 1" rgb2=".9 .91 .93" width="800" height="800"/>

    <material name="self" rgba=".7 .5 .3 1"/>
    <material name="self_default" rgba=".7 .5 .3 1"/>
    <material name="self_highlight" rgba="0 .5 .3 1"/>
    <material name="effector" rgba=".7 .4 .2 1"/>
    <material name="effector_default" rgba=".7 .4 .2 1"/>
    <material name="effector_highlight" rgba="0 .5 .3 1"/>
    <material name="decoration" rgba=".2 .6 .3 1"/>
    <material name="eye" rgba="0 .2 1 1"/>
    <material name="target" rgba=".6 .3 .3 1"/>
    <material name="target_default" rgba=".6 .3 .3 1"/>
    <material name="target_highlight" rgba=".6 .3 .3 .4"/>
    <material name="site" rgba=".5 .5 .5 .3"/>
  </asset>

  <worldbody>
    <light diffuse=".5 .5 .5" pos="0 0 3" dir="0 0 -1"/>
    <geom name="floor" type="plane" conaffinity="1" size="100 100 .2" material="blue_grid"/>
    <body name="goal" mocap="true" pos="0.0 0.0 8.5" quat="0.0 0.70710678 0.0 0.70710678">
      <geom type="sphere" size="0.05" contype="0" conaffinity="0" rgba="0 1 0 .5"/>
    </body>
    <body name="goal2" mocap="true" pos="0.5 0.0 0.0" quat="0.0 0.70710678 0.0 0.70710678">
      <geom type="sphere" size="0.05" contype="0" conaffinity="0" rgba="0 1 0 .5"/>
    </body>
     <body name="goal3" mocap="true" pos="0.0 0.5 0.0" quat="0.0 0.70710678 0.0 0.70710678">
      <geom type="sphere" size="0.05" contype="0" conaffinity="0" rgba="0 1 0 .5"/>
    </body>
     <body name="goal4" mocap="true" pos="0.0 0.0 3.0" quat="0.0 0.70710678 0.0 0.70710678">
      <geom type="sphere" size="0.05" contype="0" conaffinity="0" rgba="0 1 0 .5"/>
    </body>

    <body name="quadrotor" pos="0 0 0.1">
      <geom name="core" type="box" pos="0 0 0" quat = "1. 0. 0. 0" size="0.06 0.035 0.025"  rgba="0.3 0.3 0.8 1" mass = ".2"/>

      <body name="a00" pos=".071 0.071 0.0" quat = ".924 0.0 0.0 0.383">
        <joint name="tilta00" type="hinge" axis="1 0 0" />
        <geom type="box" size="0.05 0.01 0.0025"  rgba="0.5 0.5 0.5 1" mass="0.025"/>
        <geom name="thruster0" type="cylinder" pos=" 0.029  0  0.01" size="0.05 0.0025"  rgba="0.5 0.5 0.5 1" mass="0.025"/>
      </body>
      
      <geom name="a10" type="box" pos=".071 -0.071 0.0" size="0.05 0.01 0.0025"  quat = ".383 0.0 0.0 0.924" rgba="0.5 0.5 0.5 1" mass = ".025"/>
      <geom name="a20" type="box" pos="-0.071 -0.071 0.0" size="0.05 0.01 0.0025"  quat = "-.383 0.0 0.0 0.924" rgba="0.5 0.5 0.5 1" mass = ".025"/>
      <geom name="a30" type="box" pos="-.071 0.071 0.0" size="0.05 0.01 0.0025"  quat = ".924 0.0 0.0 -0.383" rgba="0.5 0.5 0.5 1" mass = ".025"/>

      <joint name="root"   type="free" damping="0" armature="0" pos="0 0 0" />

      <!-- Actuator sites to attach actuators  -->
      <site name="thrust" type="box" pos="0 0 0"  size="0.06 0.035 0.025"  quat = "1.0 0.0 0.0 0." rgba="0.5 0.5 0.5 1"/>
      <site name="sensor" type="box" pos="0 0 0"  size="0.06 0.035 0.025"  quat = "0.0 0.0 0.0 1." rgba="0.5 0.5 0.5 1"/>

      <site name="rateX" type="box" pos="0 0 0" quat = "1. 0. 0. 0."  size="0.06 0.035 0.025" rgba="0.5 0.5 0.5 1" />
      <site name="rateY" type="box" pos="0 0 0" quat = "1. 0. 0. 0."  size="0.06 0.035 0.025" rgba="0.5 0.5 0.5 1" />
      <site name="rateZ" type="box" pos="0 0 0" quat = "1. 0. 0. 0."  size="0.06 0.035 0.025" rgba="0.5 0.5 0.5 1" />

      <!-- Thruster geometries for collisions since site's are excluded from collision checking -->
      <geom name="thruster1" type="cylinder" pos=" 0.1 -0.1  0.01" size="0.05 0.0025"  rgba="0.5 0.5 0.5 1" mass = ".025"/>
      <geom name="thruster2" type="cylinder" pos="-0.1 -0.1  0.01" size="0.05 0.0025"  rgba="0.5 0.5 0.5 1" mass = ".025"/>
      <geom name="thruster3" type="cylinder" pos="-0.1  0.1  0.01" size="0.05 0.0025"  rgba="0.5 0.5 0.5 1" mass = ".025"/>
      <site name="thruster0" type="cylinder" pos=" 0.1  0.1  0.01" size="0.005 0.00025"  rgba="0.5 0.5 0.5 1"/>
      <site name="thruster1" type="cylinder" pos=" 0.1 -0.1  0.01" size="0.005 0.00025"  rgba="0.5 0.5 0.5 1"/>
      <site name="thruster2" type="cylinder" pos="-0.1 -0.1  0.01" size="0.005 0.00025"  rgba="0.5 0.5 0.5 1"/>
      <site name="thruster3" type="cylinder" pos="-0.1  0.1  0.01" size="0.005 0.00025"  rgba="0.5 0.5 0.5 1"/>

            <!-- Visualization of the coordinate frame -->
      <!-- <site name="qcX" type="box" pos="0.1 0.0 0.0" size="0.1 0.005 0.005"  quat = " 1.000  0.0  0.0    0."     rgba="1 0 0 1" />
      <site name="qcY" type="box" pos="0.0 0.1 0.0" size="0.1 0.005 0.005"  quat = " 0.707  0.0  0.0    0.707"  rgba="0 1 0 1" />
      <site name="qcZ" type="box" pos="0.0 0.0 0.1" size="0.1 0.005 0.005"  quat = "-0.707  0.0  0.707  0."     rgba="0 0 1 1" /> -->
    </body>
  </worldbody>
    <actuator>
      <motor ctrllimited="true" ctrlrange="0.0 1.0" gear="0  0. 5. 0. 0. .1" site="thruster0"/>
      <motor ctrllimited="true" ctrlrange="0.0 1.0" gear="0  0. 5. 0. 0. -.1" site="thruster1"/>
      <motor ctrllimited="true" ctrlrange="0.0 1.0" gear="0  0. 5. 0. 0. .1" site="thruster2"/>
      <motor ctrllimited="true" ctrlrange="0.0 1.0" gear="0  0. 5. 0. 0. -.1" site="thruster3"/>

      <velocity ctrllimited="true" ctrlrange="-1.0 1.0" name="a00servov" joint="tilta00" kv="0.003" />
    </actuator>
    <sensor>
    <velocimeter site="thrust"/>
  </sensor>
    <sensor>
    <rangefinder site="sensor"/>
  </sensor>

</mujoco>
