<mujoco model="Quadrotor">
  <compiler inertiafromgeom="true" coordinate="local"/>
  <option timestep="0.01" gravity="0 0 -9.81" wind="0 0 0" density="1.225" viscosity="1.48e-5" />

  <asset>
    <texture name="blue_grid" type="2d" builtin="checker" rgb1=".02 .14 .44" rgb2=".27 .55 1" width="300" height="300" mark="edge" markrgb="1 1 1"/>
    <material name="blue_grid" texture="blue_grid" texrepeat="1 1" texuniform="true" reflectance=".2"/>

    <texture name="grey_grid" type="2d" builtin="checker" rgb1=".26 .26 .26" rgb2=".6 .6 .6" width="300" height="300" mark="edge" markrgb="1 1 1"/>
    <material name="grey_grid" texture="blue_grid" texrepeat="1 1" texuniform="true" reflectance=".2"/>
    <texture name="skybox" type="skybox" builtin="gradient" rgb1=".66 .79 1" rgb2=".9 .91 .93" width="800" height="800"/>

    <material name="self" rgba=".7 .5 .3 1"/>
    <material name="self_default" rgba=".7 .5 .3 1"/>
    <material name="self_highlight" rgba="0 .5 .3 1"/>
    <material name="effector" rgba=".7 .4 .2 1"/>
    <material name="effector_default" rgba=".7 .4 .2 1"/>
    <material name="effector_highlight" rgba="0 .5 .3 1"/>
    <material name="decoration" rgba=".2 .6 .3 1"/>
    <material name="eye" rgba="0 .2 1 1"/>
    <material name="target" rgba=".6 .3 .3 1"/>
    <material name="target_default" rgba=".6 .3 .3 1"/>
    <material name="target_highlight" rgba=".6 .3 .3 .4"/>
    <material name="site" rgba=".5 .5 .5 .3"/>
  </asset>

  <worldbody>
    <light diffuse=".5 .5 .5" pos="0 0 3" dir="0 0 -1"/>
    <geom name="floor" type="plane" conaffinity="1" size="100 100 .2" material="blue_grid"/>
    <body name="goal" mocap="true" pos="0.0 0.0 8.5" quat="0.0 0.70710678 0.0 0.70710678">
      <geom type="sphere" size="0.05" contype="0" conaffinity="0" rgba="0 1 0 .5"/>
    </body>
    <body name="goal2" mocap="true" pos="0.5 0.0 0.0" quat="0.0 0.70710678 0.0 0.70710678">
      <geom type="sphere" size="0.05" contype="0" conaffinity="0" rgba="0 1 0 .5"/>
    </body>
     <body name="goal3" mocap="true" pos="0.0 0.5 0.0" quat="0.0 0.70710678 0.0 0.70710678">
      <geom type="sphere" size="0.05" contype="0" conaffinity="0" rgba="0 1 0 .5"/>
    </body>
     <body name="goal4" mocap="true" pos="0.0 0.0 3.0" quat="0.0 0.70710678 0.0 0.70710678">
      <geom type="sphere" size="0.05" contype="0" conaffinity="0" rgba="0 1 0 .5"/>
    </body>

    <body name="quadrotor" pos="0 0 0.1">
      <body name="core" pos="0 0 0" quat = ".924 0.0 0.0 0.383">
        <geom type="box" size="0.06 0.035 0.025"  rgba="0.3 0.3 0.8 1" mass = ".2"/>
        <site name="thrust" type="box" />
      </body> 
      <body name="a00" pos=".071 0.071 0.0" quat = ".924 0.0 0.0 0.383">
        <joint name="tilta00" type="hinge" axis="-1 0 0"/>
        <geom type="box" size="0.05 0.01 0.0025"  rgba="0.5 0.5 0.5 1" mass="0.025"/>
        <geom name="thruster0" type="cylinder" pos=" 0.029  0  0.01" size="0.05 0.0025"  rgba="0 1.0 0 1" mass="0.025"/>
        <site name="thruster0" type="cylinder"/>
      </body>



      <body name="a20" pos="-0.071 -0.071 0.0" quat = "-.383 0.0 0.0 0.924">
        <joint name="tilta20" type="hinge" axis="-1 0 0"/>
        <geom type="box" size="0.05 0.01 0.0025"  rgba="0.5 0.5 0.5 1" mass="0.025"/>
        <geom name="thruster2" type="cylinder" pos=" 0.029  0  0.01" size="0.05 0.0025"  rgba="0.0 0.5 0.5 1" mass="0.025"/>
        <site name="thruster2" type="cylinder"/>
      </body>

      <body name="a30" pos="0.071 -0.071 0.0" quat = ".383 0.0 0.0 0.924">
        <joint name="tilta30" type="hinge" axis="1 0 0"/>
        <geom type="box" size="0.05 0.01 0.0025"  rgba="0.5 0.5 0.5 1" mass="0.025"/>
        <geom name="thruster3" type="cylinder" pos=" -0.029  0  0.01" size="0.05 0.0025"  rgba="1.0 0.5 0 1" mass="0.025"/>
        <site name="thruster3" type="cylinder"/>
      </body>
      

      <body name="a40" pos="-0.071 0.071 0.0" quat = ".924 0.0 0.0 -.383">
        <joint name="tilta40" type="hinge" axis="1 0 0"/>
        <geom type="box" size="0.05 0.01 0.0025"  rgba="0.5 0.5 0.5 1" mass="0.025"/>
        <geom name="thruster4" type="cylinder" pos="-0.029  0  0.01" size="0.05 0.0025"  rgba="1.0 0.5 0.5 1" mass="0.025"/>
        <site name="thruster4" type="cylinder"/>
      </body>
      
      <!-- <geom name="a20" type="box" pos="-0.071 -0.071 0.0" size="0.05 0.01 0.0025"  quat = "-.383 0.0 0.0 0.924" rgba="0.5 0.5 0.5 1" mass = ".025"/> -->



      <joint name="root"   type="free" damping="0" armature="0" pos="0 0 0" />

      <!-- Actuator sites to attach actuators  -->
      <site name="sensor" type="box" pos="0 0 0"  size="0.06 0.035 0.025"  quat = "0.924 0.0 0.0 0.383" rgba="0.5 0.5 0.5 1"/>


      <!-- Thruster geometries for collisions since site's are excluded from collision checking -->


            <!-- Visualization of the coordinate frame -->
      <!-- <site name="qcX" type="box" pos="0.1 0.0 0.0" size="0.1 0.005 0.005"  quat = " 1.000  0.0  0.0    0."     rgba="1 0 0 1" />
      <site name="qcY" type="box" pos="0.0 0.1 0.0" size="0.1 0.005 0.005"  quat = " 0.707  0.0  0.0    0.707"  rgba="0 1 0 1" />
      <site name="qcZ" type="box" pos="0.0 0.0 0.1" size="0.1 0.005 0.005"  quat = "-0.707  0.0  0.707  0."     rgba="0 0 1 1" /> -->
    </body>
  </worldbody>
    <actuator>
      <motor ctrllimited="true" ctrlrange="0.0 1.0" gear="0  0. 5. 0. 0. .1" site="thruster0"/>
      <motor ctrllimited="true" ctrlrange="0.0 1.0" gear="0  0. 5. 0. 0. .1" site="thruster3"/>

      <motor ctrllimited="true" ctrlrange="0.0 1.0" gear="0  0. 5. 0. 0. -.1" site="thruster2"/>
      <motor ctrllimited="true" ctrlrange="0.0 1.0" gear="0  0. 5. 0. 0. -.1" site="thruster4"/>
      <motor gear="1" joint="tilta00"/>
      <motor gear="1" joint="tilta30"/>

      <motor gear="1" joint="tilta20"/>
      <motor gear="1" joint="tilta40"/>
    </actuator>
    <sensor>
      <!-- <velocimeter site="thrust"/> -->
      <!-- <rangefinder site="sensor"/> -->
      <jointpos name="tiltangle1" joint="tilta00"/>
      <jointvel name="tiltvel1" joint="tilta00"/>
      <jointpos name="tiltangle3" joint="tilta30"/>
      <jointvel name="tiltvel3" joint="tilta30"/>
      <jointpos name="tiltangle2" joint="tilta20"/>
      <jointvel name="tiltvel2" joint="tilta20"/>

      <jointpos name="tiltangle4" joint="tilta40"/>
      <jointvel name="tiltvel4" joint="tilta40"/>

      <accelerometer name="xyzacc" site = "thrust"/>
      <velocimeter name="xyzvel" site = "thrust"/>
      <gyro name="rpyvel" site = "thrust"/>


    </sensor>
</mujoco>